Workbook

Sheet Summary
B2: Corporate analysis
B3: 2026.04.01
B4: Summary | D4: (단위:백만원) | E4: 2021 | F4: 2022 | G4: 2023 | H4: 2024 | I4: 2025 | J4: CAGR (2020~24) | K4: Financials | Y4: Industry/Corporate Analysis | Z4: Investment Highlights / Risk Factors | AA4: Comments
B5: No. | C5: 1 | D5: 매출액 | E5: ='1'!B6 -> 17851906 | F5: ='1'!C6 -> 25598609 | G5: ='1'!D6 -> 33745470 | H5: ='1'!E6 -> 25619585 | I5: ='1'!F6 -> 23671759 | J5: =IFERROR(RATE(4,,-E5,I5),"") -> 0.073090833 | K5: (단위:백만원) | L5: No. of Shares | M5: Stock Price | N5: Market Cap | O5: 현금흐름 분석 | T5: 현금성자산 / 부채비율
B6: 회사명 | C6: ='1'!B3 -> LG에너지솔루션 | D6: EBIT | E6: ='1'!B7 -> 768470 | F6: ='1'!C7 -> 1213719 | G6: ='1'!D7 -> 2163234 | H6: ='1'!E7 -> 575387 | I6: ='1'!F7 -> 1346120 | J6: =IFERROR(RATE(4,,-E6,I6),"") -> 0.15044064 | K6: Market Cap | L6: 234000000 | M6: 488000 | N6: =L6*M6/1000000 -> 114192000
B7: 상장여부 | C7: ='1'!D3 -> 코스피 | D7: EBITDA | E7: ='1'!B10 -> 2186278 | F7: ='1'!C10 -> 3056432 | G7: ='1'!D10 -> 4450113 | H7: ='1'!E10 -> 3621171 | I7: ='1'!F10 -> 5037370 | J7: =IFERROR(RATE(4,,-E7,I7),"") -> 0.23203946 | K7: PER | N7: =IFERROR(N6/I8,"-") -> 1413.2149
B8: 시가총액 | C8: =N6 -> 114192000 | D8: 당기순이익(손실) | E8: ='1'!B11 -> 929868 | F8: ='1'!C11 -> 779826 | G8: ='1'!D11 -> 1637985 | H8: ='1'!E11 -> 338602 | I8: ='1'!F11 -> 80803 | J8: =IFERROR(RATE(4,,-E8,I8),"") -> -0.45706037 | K8: EV (Enterprise Value) | N8: =IFERROR(N6+I17,"-") -> 132924789
B9: 매출액 | C9: =I5 -> 23671759 | D9: EBIT/매출액(%) | E9: =IFERROR(E6/E5,"") -> 0.043046944 | F9: =IFERROR(F6/F5,"") -> 0.047413475 | G9: =IFERROR(G6/G5,"") -> 0.064104426 | H9: =IFERROR(H6/H5,"") -> 0.022458873 | I9: =IFERROR(I6/I5,"") -> 0.056866074 | J9: =IFERROR(RATE(4,,-E9,I9),"") -> 0.072081322 | K9: EV / EBITDA | N9: =IFERROR(N8/I7,"-") -> 26.387736
B10: EBITDA | C10: =I7 -> 5037370 | D10: EBITDA Margin(%) | E10: =IFERROR(E7/E5,"") -> 0.12246748 | F10: =IFERROR(F7/F5,"") -> 0.11939836 | G10: =IFERROR(G7/G5,"") -> 0.1318729 | H10: =IFERROR(H7/H5,"") -> 0.14134386 | I10: =IFERROR(I7/I5,"") -> 0.21280083 | J10: =IFERROR(RATE(4,,-E10,I10),"") -> 0.14812225
B11: PER | C11: =N7 -> 1413.2149 | D11: 당기순이익(%) | E11: =IFERROR(E8/E5,"") -> 0.052087884 | F11: =IFERROR(F8/F5,"") -> 0.030463608 | G11: =IFERROR(G8/G5,"") -> 0.048539404 | H11: =IFERROR(H8/H5,"") -> 0.013216529 | I11: =IFERROR(I8/I5,"") -> 0.0034134768 | J11: =IFERROR(RATE(4,,-E11,I11),"") -> -0.49404131
B12: EV/EBITDA | C12: =N9 -> 26.387736 | D12: 자산 | E12: ='1'!B12 -> 23764137 | F12: ='1'!C12 -> 38299445 | G12: ='1'!D12 -> 45437144 | H12: ='1'!E12 -> 60306791 | I12: ='1'!F12 -> 67147953 | J12: =IFERROR(RATE(4,,-E12,I12),"") -> 0.29651541
D13: 부채 | E13: ='1'!B13 -> 15021764 | F13: ='1'!C13 -> 17705683 | G13: ='1'!D13 -> 21063635 | H13: ='1'!E13 -> 29340248 | I13: ='1'!F13 -> 37826277 | J13: =IFERROR(RATE(4,,-E13,I13),"") -> 0.25970301
D14: 자본 | E14: ='1'!B14 -> 8742373 | F14: ='1'!C14 -> 20593762 | G14: ='1'!D14 -> 24373509 | H14: ='1'!E14 -> 30966543 | I14: ='1'!F14 -> 29321676 | J14: =IFERROR(RATE(4,,-E14,I14),"") -> 0.35328686
D15: 총차입금 | E15: ='1'!B17 -> 6969193 | F15: ='1'!C17 -> 8109253 | G15: ='1'!D17 -> 10932288 | H15: ='1'!E17 -> 15390551 | I15: ='1'!F17 -> 22512096 | J15: =IFERROR(RATE(4,,-E15,I15),"") -> 0.34062823
D16: 현금성자산 | E16: ='1'!B18 -> 1282880 | F16: ='1'!C18 -> 5937967 | G16: ='1'!D18 -> 5068783 | H16: ='1'!E18 -> 3898711 | I16: ='1'!F18 -> 3779307 | J16: =IFERROR(RATE(4,,-E16,I16),"") -> 0.3101063
D17: 순차입금(Net Debt) | E17: =E15-E16 -> 5686313 | F17: =F15-F16 -> 2171286 | G17: =G15-G16 -> 5863505 | H17: =H15-H16 -> 11491840 | I17: =I15-I16 -> 18732789 | O17: CAPEX 집중 투자 사이클(투자현금흐름 -6.3조 -> -12.1조 -> -10.9조)
D18: 부채비율(%) | E18: =IFERROR(E13/E14,"") -> 1.7182708 | F18: =IFERROR(F13/F14,"") -> 0.85975952 | G18: =IFERROR(G13/G14,"") -> 0.86420199 | H18: =IFERROR(H13/H14,"") -> 0.94748219 | I18: =IFERROR(I13/I14,"") -> 1.2900448 | O18: ㄴ 북미 JV, 애리조나 공장 등 연간 10-12조 투자로부터 기인
D19: 영업활동현금흐름 | E19: ='1'!B20 -> 978585 | F19: ='1'!C20 -> -579807 | G19: ='1'!D20 -> 4444179 | H19: ='1'!E20 -> 5111700 | I19: ='1'!F20 -> 4432277 | O19: 영업현금흐름 개선 기반 수익구조 전환(EBITDA 기반 현금창출력 회복)
D20: 투자활동현금흐름 | E20: ='1'!B21 -> -2178121 | F20: ='1'!C21 -> -6259356 | G20: ='1'!D21 -> -9719327 | H20: ='1'!E21 -> -12065447 | I20: ='1'!F21 -> -10881277 | O20: 투자 > 영업 구조에 따른 FCF 적자 지속
D21: 재무활동현금흐름 | E21: ='1'!B22 -> 882835 | F21: ='1'!C22 -> 11414617 | G21: ='1'!D22 -> 4354690 | H21: ='1'!E22 -> 5381505 | I21: ='1'!F22 -> 6285926 | O21: 재무현금흐름 기반 구조 확립: 대규모 증설 자금 외부 조달 의존
B22: No. | C22: 2 | D22: 매출액 | E22: ='2'!B6 -> 0 | F22: ='2'!C6 -> 0 | G22: ='2'!D6 -> 0 | H22: ='2'!E6 -> 0 | I22: ='2'!F6 -> 0 | J22: =IFERROR(RATE(4,,-E22,I22),"") | K22: (단위:백만원) | L22: No. of Shares | M22: Stock Price | N22: Market Cap | O22: 현금흐름 분석 | T22: 현금성자산
B23: 회사명 | C23: ='2'!B3 -> 0 | D23: EBIT | E23: ='2'!B7 -> 0 | F23: ='2'!C7 -> 0 | G23: ='2'!D7 -> 0 | H23: ='2'!E7 -> 0 | I23: ='2'!F7 -> 0 | J23: =IFERROR(RATE(4,,-E23,I23),"-") -> - | K23: Market Cap | N23: =L23*M23/1000000 -> 0
B24: 상장여부 | C24: ='2'!D3 -> 0 | D24: EBITDA | E24: ='2'!B10 -> 0 | F24: ='2'!C10 -> 0 | G24: ='2'!D10 -> 0 | H24: ='2'!E10 -> 0 | I24: ='2'!F10 -> 0 | J24: =IFERROR(RATE(4,,-E24,I24),"-") -> - | K24: PER | N24: =IFERROR(N23/I25,"-") -> -
B25: 시가총액 | C25: =N23 -> 0 | D25: 당기순이익(손실) | E25: ='2'!B11 -> 0 | F25: ='2'!C11 -> 0 | G25: ='2'!D11 -> 0 | H25: ='2'!E11 -> 0 | I25: ='2'!F11 -> 0 | J25: =IFERROR(RATE(4,,-E25,I25),"-") -> - | K25: EV (Enterprise Value) | N25: =IFERROR(N23+I34,"-") -> 0
B26: 매출액 | C26: =I22 -> 0 | D26: EBIT/매출액(%) | E26: =IFERROR(E23/E22,"") | F26: =IFERROR(F23/F22,"") | G26: =IFERROR(G23/G22,"") | H26: =IFERROR(H23/H22,"") | I26: =IFERROR(I23/I22,"") | J26: =IFERROR(RATE(4,,-E26,I26),"-") -> - | K26: EV / EBITDA | N26: =IFERROR(N25/I24,"-") -> -
B27: EBITDA | C27: =I24 -> 0 | D27: EBITDA Margin(%) | E27: =IFERROR(E24/E22,"") | F27: =IFERROR(F24/F22,"") | G27: =IFERROR(G24/G22,"") | H27: =IFERROR(H24/H22,"") | I27: =IFERROR(I24/I22,"") | J27: =IFERROR(RATE(4,,-E27,I27),"-") -> -
B28: PER | C28: =N24 -> - | D28: 당기순이익(%) | E28: =IFERROR(E25/E22,"") | F28: =IFERROR(F25/F22,"") | G28: =IFERROR(G25/G22,"") | H28: =IFERROR(H25/H22,"") | I28: =IFERROR(I25/I22,"") | J28: =IFERROR(RATE(4,,-E28,I28),"-") -> -
B29: EV/EBITDA | C29: =N26 -> - | D29: 자산 | E29: ='2'!B12 -> 0 | F29: ='2'!C12 -> 0 | G29: ='2'!D12 -> 0 | H29: ='2'!E12 -> 0 | I29: ='2'!F12 -> 0 | J29: =IFERROR(RATE(4,,-E29,I29),"")
D30: 부채 | E30: ='2'!B13 -> 0 | F30: ='2'!C13 -> 0 | G30: ='2'!D13 -> 0 | H30: ='2'!E13 -> 0 | I30: ='2'!F13 -> 0 | J30: =IFERROR(RATE(4,,-E30,I30),"")
D31: 자본 | E31: ='2'!B14 -> 0 | F31: ='2'!C14 -> 0 | G31: ='2'!D14 -> 0 | H31: ='2'!E14 -> 0 | I31: ='2'!F14 -> 0 | J31: =IFERROR(RATE(4,,-E31,I31),"")
D32: 총차입금 | E32: ='2'!B17 -> 0 | F32: ='2'!C17 -> 0 | G32: ='2'!D17 -> 0 | H32: ='2'!E17 -> 0 | I32: ='2'!F17 -> 0 | J32: =IFERROR(RATE(4,,-E32,I32),"")
D33: 현금성자산 | E33: ='2'!B18 -> 0 | F33: ='2'!C18 -> 0 | G33: ='2'!D18 -> 0 | H33: ='2'!E18 -> 0 | I33: ='2'!F18 -> 0 | J33: =IFERROR(RATE(4,,-E33,I33),"")
D34: 순차입금(Net Debt) | E34: ='2'!B19 -> 0 | F34: ='2'!C19 -> 0 | G34: ='2'!D19 -> 0 | H34: ='2'!E19 -> 0 | I34: ='2'!F19 -> 0
D35: 부채비율(%) | E35: =IFERROR(E30/E31,"") | F35: =IFERROR(F30/F31,"") | G35: =IFERROR(G30/G31,"") | H35: =IFERROR(H30/H31,"") | I35: =IFERROR(I30/I31,"")
D36: 영업활동현금흐름 | E36: ='2'!B20 -> 0 | F36: ='2'!C20 -> 0 | G36: ='2'!D20 -> 0 | H36: ='2'!E20 -> 0 | I36: ='2'!F20 -> 0
D37: 투자활동현금흐름 | E37: ='2'!B21 -> 0 | F37: ='2'!C21 -> 0 | G37: ='2'!D21 -> 0 | H37: ='2'!E21 -> 0 | I37: ='2'!F21 -> 0
D38: 재무활동현금흐름 | E38: ='2'!B22 -> 0 | F38: ='2'!C22 -> 0 | G38: ='2'!D22 -> 0 | H38: ='2'!E22 -> 0 | I38: ='2'!F22 -> 0
B39: No. | C39: 3 | D39: 매출액 | E39: ='3'!B6 -> 0 | F39: ='3'!C6 -> 0 | G39: ='3'!D6 -> 0 | H39: ='3'!E6 -> 0 | I39: ='3'!F6 -> 0 | J39: =IFERROR(RATE(4,,-E39,I39),"") | K39: (단위:백만원) | L39: No. of Shares | M39: Stock Price | N39: Market Cap | O39: 현금흐름 분석 | T39: 현금성자산
B40: 회사명 | C40: ='3'!B3 -> 0 | D40: EBIT | E40: ='3'!B7 -> 0 | F40: ='3'!C7 -> 0 | G40: ='3'!D7 -> 0 | H40: ='3'!E7 -> 0 | I40: ='3'!F7 -> 0 | J40: =IFERROR(RATE(4,,-E40,I40),"") | K40: Market Cap | N40: =L40*M40/1000000 -> 0
B41: 상장여부 | C41: ='3'!D3 -> 0 | D41: EBITDA | E41: ='3'!B10 -> 0 | F41: ='3'!C10 -> 0 | G41: ='3'!D10 -> 0 | H41: ='3'!E10 -> 0 | I41: ='3'!F10 -> 0 | J41: =IFERROR(RATE(4,,-E41,I41),"") | K41: PER | N41: =IFERROR(N40/I42,"")
...

Sheet 1
D2: 코스피, 코스닥, 코넥스, 비상장
A3: 회사명 | B3: LG에너지솔루션 | C3: 상장여부 | D3: 코스피 | G3: (단위: 백만)
B5: 2021 | C5: 2022 | D5: 2023 | E5: 2024 | F5: 2025 | G5: data
A6: 매출액(수익) | B6: 17851906 | C6: 25598609 | D6: 33745470 | E6: 25619585 | F6: 23671759 | G6: 손익계산서 | I6: 손익계산서 | J6: 재무상태표 | K6: 현금흐름표
A7: 영업이익(EBIT) | B7: 768470 | C7: 1213719 | D7: 2163234 | E7: 575387 | F7: 1346120 | I7: 참조 | J7: 참조 | K7: (주석) 참조
A8: 감가상각비 | B8: 1347384 | C8: 1745493 | D8: 2150207 | E8: 2856045 | F8: 3413557 | G8: 현금흐름표 or 현금흐름표(주석)
A9: 무형자산상각비 | B9: 70424 | C9: 97220 | D9: 136672 | E9: 189739 | F9: 277693
A10: EBITDA | B10: =B7+B8+B9 -> 2186278 | C10: =C7+C8+C9 -> 3056432 | D10: =D7+D8+D9 -> 4450113 | E10: =E7+E8+E9 -> 3621171 | F10: =F7+F8+F9 -> 5037370 | G10: 자동계산 | I10: EBITDA = 영업이익 + 감가상각비 (Depreciation) + 무형자산상각비 (Amortization)
A11: 당기순이익 | B11: 929868 | C11: 779826 | D11: 1637985 | E11: 338602 | F11: 80803 | G11: 손익계산서
A12: 자산총계 | B12: 23764137 | C12: 38299445 | D12: 45437144 | E12: 60306791 | F12: 67147953 | G12: 재무상태표
A13: 부채총계 | B13: 15021764 | C13: 17705683 | D13: 21063635 | E13: 29340248 | F13: 37826277
A14: 자본총계 | B14: 8742373 | C14: 20593762 | D14: 24373509 | E14: 30966543 | F14: 29321676
A15: 단기차입금 | B15: 2203376 | C15: 2866701 | D15: 3211456 | E15: 2490240 | F15: 6686206
A16: 장기차입금 | B16: 4765817 | C16: 5242552 | D16: 7720832 | E16: 12900311 | F16: 15825890
A17: 총차입금 | B17: =B15+B16 -> 6969193 | C17: =C15+C16 -> 8109253 | D17: =D15+D16 -> 10932288 | E17: =E15+E16 -> 15390551 | F17: =F15+F16 -> 22512096 | G17: 자동계산 | I17: 총차입금 = 단기차입금 + 장기차입금
A18: 현금성자산 | B18: 1282880 | C18: 5937967 | D18: 5068783 | E18: 3898711 | F18: 3779307 | G18: 재무상태표
A19: 순차입금(net debt) | B19: =B17-B18 -> 5686313 | C19: =C17-C18 -> 2171286 | D19: =D17-D18 -> 5863505 | E19: =E17-E18 -> 11491840 | F19: =F17-F18 -> 18732789 | G19: 자동계산 | I19: 순차입금(net debt) = 총차입금 - 현금성자산
A20: 영업활동현금흐름 (cash flows from operations) | B20: 978585 | C20: -579807 | D20: 4444179 | E20: 5111700 | F20: 4432277 | G20: 현금흐름표
A21: 투자활동현금흐름 (cash flows from investing) | B21: -2178121 | C21: -6259356 | D21: -9719327 | E21: -12065447 | F21: -10881277
A22: 재무활동현금흐름 (cash flows from financing) | B22: 882835 | C22: 11414617 | D22: 4354690 | E22: 5381505 | F22: 6285926
A24: * 'Summary' sheet의 No. of shares(발행주식의 총수) 및 Stock price는 Finance.naver.com에서 검색
A25: ** template의 '단위는 백만'. 따라서 dart에서 '단위가 원'인 숫자 그대로 입력하면 summary로 가져올 때 '/10^6' 수식이 들어가있어 백만단위로 표시됨. 단, 삼성전자처럼 dart에 백만단위로 들어가 있는 회사는 수식에서 '/10^6' 삭제
A26: *** 감가상각비는 사업보고서 상, 2년치만 있는 경우가 많아, 5개년 숫자를 넣으려면 사업보고서를 세 개 참고하셔야 할 수도 (ex, 2024년 / 2022년 / 2020년 사업보고서)
A27: **** 제일 위 회사명과 상장여부 파란색 셀은 직접 입력. (상장여부는 3가지 옵션 '코스피/코스닥/코넥스/비상장' 중 하나 선택)

Sheet 2
D2: 코스피, 코스닥, 코넥스, 비상장
A3: 회사명 | C3: 상장여부 | G3: (단위: 백만)
B5: 2021 | C5: 2022 | D5: 2023 | E5: 2024 | F5: 2025 | G5: data
A6: 매출액(수익) | G6: 손익계산서 | I6: 손익계산서 | J6: 재무상태표 | K6: 현금흐름표
A7: 영업이익(EBIT) | I7: 참조 | J7: 참조 | K7: (주석) 참조
A8: 감가상각비 | G8: 현금흐름표 or 현금흐름표(주석)
A9: 무형자산상각비
A10: EBITDA | B10: =B7+B8+B9 -> 0 | C10: =C7+C8+C9 -> 0 | D10: =D7+D8+D9 -> 0 | E10: =E7+E8+E9 -> 0 | F10: =F7+F8+F9 -> 0 | G10: 자동계산 | I10: EBITDA = 영업이익 + 감가상각비 (Depreciation) + 무형자산상각비 (Amortization)
A11: 당기순이익 | G11: 손익계산서
A12: 자산총계 | G12: 재무상태표
A13: 부채총계
A14: 자본총계
A15: 단기차입금
A16: 장기차입금
A17: 총차입금 | B17: =B15+B16 -> 0 | C17: =C15+C16 -> 0 | D17: =D15+D16 -> 0 | E17: =E15+E16 -> 0 | F17: =F15+F16 -> 0 | G17: 자동계산 | I17: 총차입금 = 단기차입금 + 장기차입금
A18: 현금성자산 | G18: 재무상태표
A19: 순차입금(net debt) | B19: =B17-B18 -> 0 | C19: =C17-C18 -> 0 | D19: =D17-D18 -> 0 | E19: =E17-E18 -> 0 | F19: =F17-F18 -> 0 | G19: 자동계산 | I19: 순차입금(net debt) = 총차입금 - 현금성자산
A20: 영업활동현금흐름 (cash flows from operations) | G20: 현금흐름표
A21: 투자활동현금흐름 (cash flows from investing)
A22: 재무활동현금흐름 (cash flows from financing)
A24: * 'Summary' sheet의 No. of shares(발행주식의 총수) 및 Stock price는 Finance.naver.com에서 검색
A25: ** template의 '단위는 백만'. 따라서 dart에서 '단위가 원'인 숫자 그대로 입력하면 summary로 가져올 때 '/10^6' 수식이 들어가있어 백만단위로 표시됨. 단, 삼성전자처럼 dart에 백만단위로 들어가 있는 회사는 수식에서 '/10^6' 삭제
A26: *** 감가상각비는 사업보고서 상, 2년치만 있는 경우가 많아, 5개년 숫자를 넣으려면 사업보고서를 세 개 참고하셔야 할 수도 (ex, 2024년 / 2022년 / 2020년 사업보고서)
A27: **** 제일 위 회사명과 상장여부 파란색 셀은 직접 입력. (상장여부는 3가지 옵션 '코스피/코스닥/코넥스/비상장' 중 하나 선택)

Sheet 3
D2: 코스피, 코스닥, 코넥스, 비상장
A3: 회사명 | C3: 상장여부 | G3: (단위: 백만)
B5: 2021 | C5: 2022 | D5: 2023 | E5: 2024 | F5: 2025 | G5: data
A6: 매출액(수익) | G6: 손익계산서 | I6: 손익계산서 | J6: 재무상태표 | K6: 현금흐름표
A7: 영업이익(EBIT) | I7: 참조 | J7: 참조 | K7: (주석) 참조
A8: 감가상각비 | G8: 현금흐름표 or 현금흐름표(주석)
A9: 무형자산상각비
A10: EBITDA | B10: =B7+B8+B9 -> 0 | C10: =C7+C8+C9 -> 0 | D10: =D7+D8+D9 -> 0 | E10: =E7+E8+E9 -> 0 | F10: =F7+F8+F9 -> 0 | G10: 자동계산 | I10: EBITDA = 영업이익 + 감가상각비 (Depreciation) + 무형자산상각비 (Amortization)
A11: 당기순이익 | G11: 손익계산서
A12: 자산총계 | G12: 재무상태표
A13: 부채총계
A14: 자본총계
A15: 단기차입금
A16: 장기차입금
A17: 총차입금 | B17: =B15+B16 -> 0 | C17: =C15+C16 -> 0 | D17: =D15+D16 -> 0 | E17: =E15+E16 -> 0 | F17: =F15+F16 -> 0 | G17: 자동계산 | I17: 총차입금 = 단기차입금 + 장기차입금
A18: 현금성자산 | G18: 재무상태표
A19: 순차입금(net debt) | B19: =B17-B18 -> 0 | C19: =C17-C18 -> 0 | D19: =D17-D18 -> 0 | E19: =E17-E18 -> 0 | F19: =F17-F18 -> 0 | G19: 자동계산 | I19: 순차입금(net debt) = 총차입금 - 현금성자산
A20: 영업활동현금흐름 (cash flows from operations) | G20: 현금흐름표
A21: 투자활동현금흐름 (cash flows from investing)
A22: 재무활동현금흐름 (cash flows from financing)
A24: * 'Summary' sheet의 No. of shares(발행주식의 총수) 및 Stock price는 Finance.naver.com에서 검색
A25: ** template의 '단위는 백만'. 따라서 dart에서 '단위가 원'인 숫자 그대로 입력하면 summary로 가져올 때 '/10^6' 수식이 들어가있어 백만단위로 표시됨. 단, 삼성전자처럼 dart에 백만단위로 들어가 있는 회사는 수식에서 '/10^6' 삭제
A26: *** 감가상각비는 사업보고서 상, 2년치만 있는 경우가 많아, 5개년 숫자를 넣으려면 사업보고서를 세 개 참고하셔야 할 수도 (ex, 2024년 / 2022년 / 2020년 사업보고서)
A27: **** 제일 위 회사명과 상장여부 파란색 셀은 직접 입력. (상장여부는 3가지 옵션 '코스피/코스닥/코넥스/비상장' 중 하나 선택)
